Workbook

Sheet Protocolo
A1: Planilla de conteos ODS — GORE de Chile (mejora M2: búsqueda ODS reproducible)
A2: Primera codificación: 2026-09-23. Codificador: Claude (asistente IA) – 1.ª codificación. Una segunda persona debe repetir la muestra de la hoja «Verificacion».
A4: Elemento | B4: Definición / regla
A5: Objetivo | B5: Medir de forma reproducible si los 16 GORE mencionan los ODS en su comunicación y planificación, y si esas menciones son retóricas o sustantivas.
A6: Ventana de búsqueda | B6: Todas las búsquedas se hicieron el 2026-09-23 (una sola jornada). Se cuentan todos los resultados indexados a esa fecha, sin filtro de años.
A7: Términos (lista base ampliada) | B7: «ODS» · «Objetivos de Desarrollo Sostenible» · «Agenda 2030» · «ODS 16» (términos núcleo) + «desarrollo sostenible» · «sostenibilidad» · «Naciones Unidas» (términos de contexto).
A8: Regla de coincidencia | B8: Se verifica cada resultado buscando el término exacto en el texto (regex): ODS = \bODS\b (mayúsculas); Objetivo(s)… admite singular o plural (enmienda 24-09-2026), «de/del» y «sostenible/sustentable»; ODS 16 admite «ODS16», «ODS N° 16». Solo los términos núcleo se codifican como menciones.
A9: Fuente 1: sitio web | B9: Buscador interno del sitio oficial (método por CMS en «Registro_sitios»). Si el buscador no existe o no filtra, se recorren todas las noticias publicadas (Valparaíso, Los Lagos) o se usa la API de WordPress (Tarapacá).
A10: Fuente 2: última cuenta pública | B10: Documento PDF de la cuenta pública más reciente publicado en el sitio. Si solo existe video, se registra como «No disponible».
A11: Fuente 3: ERD | B11: Estrategia Regional de Desarrollo vigente publicada en el sitio (o la última disponible si no hay vigente).
A12: Lectura de PDF | B12: Extracción de texto página a página (pdf.js 4.0.379 en el navegador o pdftotext); se registra n.º de páginas y caracteres. Menos de ~300 caracteres/página indica documento en imágenes → «lectura parcial».
A13: Unidad de codificación | B13: Sitio web: cada noticia/página con al menos un término núcleo verificado. Documentos: cada pasaje (página) con término núcleo; el documento se clasifica por su pasaje de mayor nivel.
A14: Retórica | B14: Solo menciona los ODS/Agenda 2030 (contexto, discurso, evento, cita) sin vincularlos a objetivos, metas, indicadores o presupuesto del GORE.
A15: Sustantiva | B15: Vincula ODS o metas ODS específicas con objetivos/lineamientos del GORE, indicadores o financiamiento (p. ej., cada eje de la ERD declara los ODS a los que contribuye; programa financiado por el Joint SDG Fund).
... A18: Limitaciones conocidas | B18: (1) Los buscadores difieren entre CMS (algunos buscan en título, otros en texto completo). (2) La regla ODS se amplió a «del/sustentable» durante la corrida; Biobío, Maule, RM, Atacama, Aysén, Ñuble y Los Ríos se hicieron con la regla anterior (se recomienda repetirlos en la verificación). (3) PDF en imágenes (Aysén, Magallanes). (4) Documentos no localizados o no procesables (ver «Documentos»).

Sheet Graficos_ODS
A1: Gráficos de los resultados ODS (Figuras 4 a 6 del paper y figura complementaria)
A2: Tablas con los datos de cada gráfico (izquierda), gráficos nativos editables (centro) e imágenes del paper (derecha). Fuente: hojas Menciones, Documentos y Mapa_17_ODS.
A4: Figura 4. Vinculación con los ODS por fuente (n.º de GORE)
A5: Fuente | B5: Sustantiva | C5: Retórica | D5: Sin mención | E5: No disponible
A6: ERD (planificación) | B6: =COUNTIF(Resumen_GORE!$F$5:$F$20,"Sustantiva") -> 7 | C6: =COUNTIF(Resumen_GORE!$F$5:$F$20,"Retórica") -> 3 | D6: =COUNTIF(Resumen_GORE!$F$5:$F$20,"Sin mención*") -> 6 | E6: =COUNTIF(Resumen_GORE!$F$5:$F$20,"No disponible") -> 0
A7: Cuenta pública (rendición de cuentas) | B7: =COUNTIF(Resumen_GORE!$E$5:$E$20,"Sustantiva") -> 0 | C7: =COUNTIF(Resumen_GORE!$E$5:$E$20,"Retórica") -> 1 | D7: =COUNTIF(Resumen_GORE!$E$5:$E$20,"Sin mención*") -> 13 | E7: =COUNTIF(Resumen_GORE!$E$5:$E$20,"No disponible") -> 2
A8: Sitio web (comunicación) | B8: =COUNTIF(Resumen_GORE!$C$5:$C$20,">0") -> 2 | C8: =COUNTIFS(Resumen_GORE!$C$5:$C$20,0,Resumen_GORE!$B$5:$B$20,">0") -> 11 | D8: =COUNTIF(Resumen_GORE!$D$5:$D$20,0) -> 3 | E8: 0
A12: Figura 6. N.º de ERD que vinculan cada ODS (de 16)
A13: ODS | B13: Vinculado a eje, objetivo o indicador | C13: Nombrado como contexto | D13: Total
A14: ODS 1 | B14: =COUNTIF(Mapa_17_ODS!D$6:D$21,2) -> 4 | C14: =COUNTIF(Mapa_17_ODS!D$6:D$21,1) -> 0 | D14: =B14+C14 -> 4
A15: ODS 2 | B15: =COUNTIF(Mapa_17_ODS!E$6:E$21,2) -> 5 | C15: =COUNTIF(Mapa_17_ODS!E$6:E$21,1) -> 0 | D15: =B15+C15 -> 5
A16: ODS 3 | B16: =COUNTIF(Mapa_17_ODS!F$6:F$21,2) -> 6 | C16: =COUNTIF(Mapa_17_ODS!F$6:F$21,1) -> 0 | D16: =B16+C16 -> 6
A17: ODS 4 | B17: =COUNTIF(Mapa_17_ODS!G$6:G$21,2) -> 6 | C17: =COUNTIF(Mapa_17_ODS!G$6:G$21,1) -> 1 | D17: =B17+C17 -> 7
A18: ODS 5 | B18: =COUNTIF(Mapa_17_ODS!H$6:H$21,2) -> 6 | C18: =COUNTIF(Mapa_17_ODS!H$6:H$21,1) -> 0 | D18: =B18+C18 -> 6
A19: ODS 6 | B19: =COUNTIF(Mapa_17_ODS!I$6:I$21,2) -> 6 | C19: =COUNTIF(Mapa_17_ODS!I$6:I$21,1) -> 0 | D19: =B19+C19 -> 6
A20: ODS 7 | B20: =COUNTIF(Mapa_17_ODS!J$6:J$21,2) -> 6 | C20: =COUNTIF(Mapa_17_ODS!J$6:J$21,1) -> 0 | D20: =B20+C20 -> 6
A21: ODS 8 | B21: =COUNTIF(Mapa_17_ODS!K$6:K$21,2) -> 6 | C21: =COUNTIF(Mapa_17_ODS!K$6:K$21,1) -> 1 | D21: =B21+C21 -> 7
A22: ODS 9 | B22: =COUNTIF(Mapa_17_ODS!L$6:L$21,2) -> 5 | C22: =COUNTIF(Mapa_17_ODS!L$6:L$21,1) -> 0 | D22: =B22+C22 -> 5
A23: ODS 10 | B23: =COUNTIF(Mapa_17_ODS!M$6:M$21,2) -> 5 | C23: =COUNTIF(Mapa_17_ODS!M$6:M$21,1) -> 1 | D23: =B23+C23 -> 6
A24: ODS 11 | B24: =COUNTIF(Mapa_17_ODS!N$6:N$21,2) -> 6 | C24: =COUNTIF(Mapa_17_ODS!N$6:N$21,1) -> 1 | D24: =B24+C24 -> 7
A25: ODS 12 | B25: =COUNTIF(Mapa_17_ODS!O$6:O$21,2) -> 6 | C25: =COUNTIF(Mapa_17_ODS!O$6:O$21,1) -> 1 | D25: =B25+C25 -> 7
A26: ODS 13 | B26: =COUNTIF(Mapa_17_ODS!P$6:P$21,2) -> 5 | C26: =COUNTIF(Mapa_17_ODS!P$6:P$21,1) -> 0 | D26: =B26+C26 -> 5
A27: ODS 14 | B27: =COUNTIF(Mapa_17_ODS!Q$6:Q$21,2) -> 5 | C27: =COUNTIF(Mapa_17_ODS!Q$6:Q$21,1) -> 0 | D27: =B27+C27 -> 5
A28: ODS 15 | B28: =COUNTIF(Mapa_17_ODS!R$6:R$21,2) -> 6 | C28: =COUNTIF(Mapa_17_ODS!R$6:R$21,1) -> 0 | D28: =B28+C28 -> 6
A29: ODS 16 | B29: =COUNTIF(Mapa_17_ODS!S$6:S$21,2) -> 5 | C29: =COUNTIF(Mapa_17_ODS!S$6:S$21,1) -> 0 | D29: =B29+C29 -> 5
A30: ODS 17 | B30: =COUNTIF(Mapa_17_ODS!T$6:T$21,2) -> 5 | C30: =COUNTIF(Mapa_17_ODS!T$6:T$21,1) -> 0 | D30: =B30+C30 -> 5
A33: Figura complementaria A1. Menciones ODS en el sitio web por GORE (23-09-2026)
A34: GORE | B34: Sustantiva | C34: Retórica | D34: Total
A35: Arica y Parinacota | B35: 0 | C35: 0 | D35: =B35+C35 -> 0
A36: Tarapacá | B36: 0 | C36: 1 | D36: =B36+C36 -> 1
A37: Antofagasta | B37: 0 | C37: 1 | D37: =B37+C37 -> 1
A38: Atacama | B38: 0 | C38: 1 | D38: =B38+C38 -> 1
A39: Coquimbo | B39: 0 | C39: 4 | D39: =B39+C39 -> 4
A40: Valparaíso | B40: 0 | C40: 7 | D40: =B40+C40 -> 7
A41: Metropolitana | B41: 0 | C41: 2 | D41: =B41+C41 -> 2
A42: O'Higgins | B42: 0 | C42: 0 | D42: =B42+C42 -> 0
A43: Maule | B43: 0 | C43: 2 | D43: =B43+C43 -> 2
A44: Ñuble | B44: 6 | C44: 0 | D44: =B44+C44 -> 6
A45: Biobío | B45: 0 | C45: 2 | D45: =B45+C45 -> 2
A46: La Araucanía | B46: 2 | C46: 1 | D46: =B46+C46 -> 3
...

Sheet Registro_sitios
A1: Registro de búsqueda en sitios web (fuente 1)
A2: Devueltos = resultados que entrega el buscador; Verificados = resultados que contienen el término exacto. «n/a» = recorrido completo sin buscador.
A4: GORE | B4: Sitio | C4: Método de búsqueda | D4: Término | E4: Tipo de término | F4: N.º devueltos | G4: N.º verificados | H4: Fecha | I4: Codificador | J4: Nota
A5: Arica y Parinacota | B5: https://www.gorearicayparinacota.cl | C5: https://www.gorearicayparinacota.cl/cgi-bin/prontus_search.cgi?search_prontus=goreayp&search_texto={termino}&search_modo=and (Prontus) | D5: ODS | E5: Núcleo | F5: 0 | G5: 0 | H5: 2026-09-23 | I5: scraping e IA | J5: El índice del buscador es pequeño (p. ej., «desarrollo» devuelve 32 resultados, casi todos de 2026), lo que sugiere un sitio renovado con poco contenido histórico indexado.
A6: Arica y Parinacota | B6: https://www.gorearicayparinacota.cl | C6: https://www.gorearicayparinacota.cl/cgi-bin/prontus_search.cgi?search_prontus=goreayp&search_texto={termino}&search_modo=and (Prontus) | D6: Objetivos de Desarrollo Sostenible | E6: Núcleo | F6: 0 | G6: 0 | H6: 2026-09-23 | I6: scraping e IA
A7: Arica y Parinacota | B7: https://www.gorearicayparinacota.cl | C7: https://www.gorearicayparinacota.cl/cgi-bin/prontus_search.cgi?search_prontus=goreayp&search_texto={termino}&search_modo=and (Prontus) | D7: Agenda 2030 | E7: Núcleo | F7: 0 | G7: 0 | H7: 2026-09-23 | I7: scraping e IA
A8: Arica y Parinacota | B8: https://www.gorearicayparinacota.cl | C8: https://www.gorearicayparinacota.cl/cgi-bin/prontus_search.cgi?search_prontus=goreayp&search_texto={termino}&search_modo=and (Prontus) | D8: ODS 16 | E8: Núcleo | F8: 0 | G8: 0 | H8: 2026-09-23 | I8: scraping e IA
A9: Arica y Parinacota | B9: https://www.gorearicayparinacota.cl | C9: https://www.gorearicayparinacota.cl/cgi-bin/prontus_search.cgi?search_prontus=goreayp&search_texto={termino}&search_modo=and (Prontus) | D9: desarrollo sostenible | E9: Contexto | F9: 1 | G9: 0 | H9: 2026-09-23 | I9: scraping e IA
A10: Arica y Parinacota | B10: https://www.gorearicayparinacota.cl | C10: https://www.gorearicayparinacota.cl/cgi-bin/prontus_search.cgi?search_prontus=goreayp&search_texto={termino}&search_modo=and (Prontus) | D10: sostenibilidad | E10: Contexto | F10: 2 | G10: 2 | H10: 2026-09-23 | I10: scraping e IA
A11: Arica y Parinacota | B11: https://www.gorearicayparinacota.cl | C11: https://www.gorearicayparinacota.cl/cgi-bin/prontus_search.cgi?search_prontus=goreayp&search_texto={termino}&search_modo=and (Prontus) | D11: Naciones Unidas | E11: Contexto | F11: 0 | G11: 0 | H11: 2026-09-23 | I11: scraping e IA
A12: Tarapacá | B12: https://www.goretarapaca.gov.cl | C12: El buscador visible (?s=) no filtra: devuelve todas las publicaciones (368 páginas). Se usó la API de búsqueda del propio sitio: /wp-json/wp/v2/{posts,pages}?search={termino}. | D12: ODS | E12: Núcleo | F12: 4 | G12: 1 | H12: 2026-09-23 | I12: scraping e IA
A13: Tarapacá | B13: https://www.goretarapaca.gov.cl | C13: El buscador visible (?s=) no filtra: devuelve todas las publicaciones (368 páginas). Se usó la API de búsqueda del propio sitio: /wp-json/wp/v2/{posts,pages}?search={termino}. | D13: Objetivos de Desarrollo Sostenible | E13: Núcleo | F13: 12 | G13: 0 | H13: 2026-09-23 | I13: scraping e IA
A14: Tarapacá | B14: https://www.goretarapaca.gov.cl | C14: El buscador visible (?s=) no filtra: devuelve todas las publicaciones (368 páginas). Se usó la API de búsqueda del propio sitio: /wp-json/wp/v2/{posts,pages}?search={termino}. | D14: Agenda 2030 | E14: Núcleo | F14: 2 | G14: 0 | H14: 2026-09-23 | I14: scraping e IA
A15: Tarapacá | B15: https://www.goretarapaca.gov.cl | C15: El buscador visible (?s=) no filtra: devuelve todas las publicaciones (368 páginas). Se usó la API de búsqueda del propio sitio: /wp-json/wp/v2/{posts,pages}?search={termino}. | D15: ODS 16 | E15: Núcleo | F15: 1 | G15: 0 | H15: 2026-09-23 | I15: scraping e IA
A16: Tarapacá | B16: https://www.goretarapaca.gov.cl | C16: El buscador visible (?s=) no filtra: devuelve todas las publicaciones (368 páginas). Se usó la API de búsqueda del propio sitio: /wp-json/wp/v2/{posts,pages}?search={termino}. | D16: desarrollo sostenible | E16: Contexto | F16: 71 | G16: 26 | H16: 2026-09-23 | I16: scraping e IA
A17: Tarapacá | B17: https://www.goretarapaca.gov.cl | C17: El buscador visible (?s=) no filtra: devuelve todas las publicaciones (368 páginas). Se usó la API de búsqueda del propio sitio: /wp-json/wp/v2/{posts,pages}?search={termino}. | D17: sostenibilidad | E17: Contexto | F17: 40 | G17: 40 | H17: 2026-09-23 | I17: scraping e IA
... A32: Atacama | B32: https://goreatacama.gob.cl | C32: https://goreatacama.gob.cl/?s={termino} (WordPress, paginado /page/N/) | D32: Naciones Unidas | E32: Contexto | F32: 9 | G32: 5 | H32: 2026-09-23 | I32: scraping e IA
A33: Coquimbo | B33: https://www.gorecoquimbo.cl | C33: https://www.gorecoquimbo.cl/cgi-bin/prontus_search.cgi?search_prontus=gore&search_texto={termino}&search_modo=and&search_pag=N (Prontus; «Resultados X al Y de N») | D33: ODS | E33: Núcleo | F33: 1 | G33: 1 | H33: 2026-09-23 | I33: scraping e IA | J33: El buscador Prontus usa modo «y» (todas las palabras), por lo que devuelve páginas que contienen las palabras por separado; la verificación exige la frase exacta. Con consultas rápidas el buscador truncó resultados; se repitió con 0,5–0,7 s entre solicitudes.
A34: Coquimbo | B34: https://www.gorecoquimbo.cl | C34: https://www.gorecoquimbo.cl/cgi-bin/prontus_search.cgi?search_prontus=gore&search_texto={termino}&search_modo=and&search_pag=N (Prontus; «Resultados X al Y de N») | D34: Objetivos de Desarrollo Sostenible | E34: Núcleo | F34: 17 | G34: 4 | H34: 2026-09-23 | I34: scraping e IA
A35: Coquimbo | B35: https://www.gorecoquimbo.cl | C35: https://www.gorecoquimbo.cl/cgi-bin/prontus_search.cgi?search_prontus=gore&search_texto={termino}&search_modo=and&search_pag=N (Prontus; «Resultados X al Y de N») | D35: Agenda 2030 | E35: Núcleo | F35: 6 | G35: 0 | H35: 2026-09-23 | I35: scraping e IA
A36: Coquimbo | B36: https://www.gorecoquimbo.cl | C36: https://www.gorecoquimbo.cl/cgi-bin/prontus_search.cgi?search_prontus=gore&search_texto={termino}&search_modo=and&search_pag=N (Prontus; «Resultados X al Y de N») | D36: ODS 16 | E36: Núcleo | F36: 0 | G36: 0 | H36: 2026-09-23 | I36: scraping e IA
A37: Coquimbo | B37: https://www.gorecoquimbo.cl | C37: https://www.gorecoquimbo.cl/cgi-bin/prontus_search.cgi?search_prontus=gore&search_texto={termino}&search_modo=and&search_pag=N (Prontus; «Resultados X al Y de N») | D37: desarrollo sostenible | E37: Contexto | F37: 103 | G37: 102 | H37: 2026-09-23 | I37: scraping e IA
A38: Coquimbo | B38: https://www.gorecoquimbo.cl | C38: https://www.gorecoquimbo.cl/cgi-bin/prontus_search.cgi?search_prontus=gore&search_texto={termino}&search_modo=and&search_pag=N (Prontus; «Resultados X al Y de N») | D38: sostenibilidad | E38: Contexto | F38: 47 | G38: 47 | H38: 2026-09-23 | I38: scraping e IA
A39: Coquimbo | B39: https://www.gorecoquimbo.cl | C39: https://www.gorecoquimbo.cl/cgi-bin/prontus_search.cgi?search_prontus=gore&search_texto={termino}&search_modo=and&search_pag=N (Prontus; «Resultados X al Y de N») | D39: Naciones Unidas | E39: Contexto | F39: 27 | G39: 27 | H39: 2026-09-23 | I39: scraping e IA
A40: Valparaíso | B40: https://www.gobiernovalparaiso.cl | C40: Sin buscador interno funcional: se recorrió el 100 % de las noticias publicadas (detalleNoticia.php?idNot=1…850, identificador en base64). | D40: ODS | E40: Núcleo | F40: n/a | G40: 2 | H40: 2026-09-23 | I40: scraping e IA
A41: Valparaíso | B41: https://www.gobiernovalparaiso.cl | C41: Sin buscador interno funcional: se recorrió el 100 % de las noticias publicadas (detalleNoticia.php?idNot=1…850, identificador en base64). | D41: Objetivos de Desarrollo Sostenible | E41: Núcleo | F41: n/a | G41: 5 | H41: 2026-09-23 | I41: scraping e IA
A42: Valparaíso | B42: https://www.gobiernovalparaiso.cl | C42: Sin buscador interno funcional: se recorrió el 100 % de las noticias publicadas (detalleNoticia.php?idNot=1…850, identificador en base64). | D42: Agenda 2030 | E42: Núcleo | F42: n/a | G42: 2 | H42: 2026-09-23 | I42: scraping e IA
A43: Valparaíso | B43: https://www.gobiernovalparaiso.cl | C43: Sin buscador interno funcional: se recorrió el 100 % de las noticias publicadas (detalleNoticia.php?idNot=1…850, identificador en base64). | D43: ODS 16 | E43: Núcleo | F43: n/a | G43: 0 | H43: 2026-09-23 | I43: scraping e IA
A44: Valparaíso | B44: https://www.gobiernovalparaiso.cl | C44: Sin buscador interno funcional: se recorrió el 100 % de las noticias publicadas (detalleNoticia.php?idNot=1…850, identificador en base64). | D44: desarrollo sostenible | E44: Contexto | F44: n/a | G44: 21 | H44: 2026-09-23 | I44: scraping e IA
A45: Valparaíso | B45: https://www.gobiernovalparaiso.cl | C45: Sin buscador interno funcional: se recorrió el 100 % de las noticias publicadas (detalleNoticia.php?idNot=1…850, identificador en base64). | D45: sostenibilidad | E45: Contexto | F45: n/a | G45: 36 | H45: 2026-09-23 | I45: scraping e IA
A46: Valparaíso | B46: https://www.gobiernovalparaiso.cl | C46: Sin buscador interno funcional: se recorrió el 100 % de las noticias publicadas (detalleNoticia.php?idNot=1…850, identificador en base64). | D46: Naciones Unidas | E46: Contexto | F46: n/a | G46: 36 | H46: 2026-09-23 | I46: scraping e IA
A47: Metropolitana | B47: https://www.gobiernosantiago.cl | C47: https://www.gobiernosantiago.cl/?s={termino} (WordPress, paginado /page/N/) | D47: ODS | E47: Núcleo | F47: 5 | G47: 1 | H47: 2026-09-23 | I47: scraping e IA
A48: Metropolitana | B48: https://www.gobiernosantiago.cl | C48: https://www.gobiernosantiago.cl/?s={termino} (WordPress, paginado /page/N/) | D48: Objetivos de Desarrollo Sostenible | E48: Núcleo | F48: 8 | G48: 2 | H48: 2026-09-23 | I48: scraping e IA
A49: Metropolitana | B49: https://www.gobiernosantiago.cl | C49: https://www.gobiernosantiago.cl/?s={termino} (WordPress, paginado /page/N/) | D49: Agenda 2030 | E49: Núcleo | F49: 3 | G49: 1 | H49: 2026-09-23 | I49: scraping e IA
A50: Metropolitana | B50: https://www.gobiernosantiago.cl | C50: https://www.gobiernosantiago.cl/?s={termino} (WordPress, paginado /page/N/) | D50: ODS 16 | E50: Núcleo | F50: 1 | G50: 0 | H50: 2026-09-23 | I50: scraping e IA
A51: Metropolitana | B51: https://www.gobiernosantiago.cl | C51: https://www.gobiernosantiago.cl/?s={termino} (WordPress, paginado /page/N/) | D51: desarrollo sostenible | E51: Contexto | F51: 89 | G51: 26 | H51: 2026-09-23 | I51: scraping e IA
A52: Metropolitana | B52: https://www.gobiernosantiago.cl | C52: https://www.gobiernosantiago.cl/?s={termino} (WordPress, paginado /page/N/) | D52: sostenibilidad | E52: Contexto | F52: 56 | G52: 55 | H52: 2026-09-23 | I52: scraping e IA
A53: Metropolitana | B53: https://www.gobiernosantiago.cl | C53: https://www.gobiernosantiago.cl/?s={termino} (WordPress, paginado /page/N/) | D53: Naciones Unidas | E53: Contexto | F53: 5 | G53: 5 | H53: 2026-09-23 | I53: scraping e IA
A54: O'Higgins | B54: https://www.goreohiggins.cl | C54: https://www.goreohiggins.cl/component/search/?searchword={termino}&searchphrase=exact&limit=200 (Joomla com_search, frase exacta) | D54: ODS | E54: Núcleo | F54: 0 | G54: 0 | H54: 2026-09-23 | I54: scraping e IA
A55: O'Higgins | B55: https://www.goreohiggins.cl | C55: https://www.goreohiggins.cl/component/search/?searchword={termino}&searchphrase=exact&limit=200 (Joomla com_search, frase exacta) | D55: Objetivos de Desarrollo Sostenible | E55: Núcleo | F55: 0 | G55: 0 | H55: 2026-09-23 | I55: scraping e IA
...

Sheet Menciones
A1: Menciones codificadas (términos núcleo verificados)
A2: Columnas amarillas: para la segunda persona. «Acuerdo» se calcula solo cuando hay segunda codificación.
A4: ID | B4: GORE | C4: Fuente | D4: Fecha / página | E4: Título o documento | F4: URL | G4: Términos | H4: Tipo (codificador 1) | I4: Justificación | J4: Tipo (codificador 2) | K4: Acuerdo | L4: Consenso final
A5: W01 | B5: Tarapacá | C5: Sitio web | D5: 2017-05-01 | E5: INJUV te invita a participar del programa de voluntariado internacional de la Alianza del Pacífico | F5: https://www.goretarapaca.gov.cl/injuv-te-invita-a-participar-del-programa-de-voluntariado-internacional-de-la-alianza-del-pacifico/ | G5: ODS | H5: Retórica | I5: Programa del INJUV «en concordancia con el ODS 11»; no es una iniciativa del GORE. | J5: Retórica | K5: =IF(J5="","",IF(J5=H5,1,0)) -> 1 | L5: Retórica
A6: W02 | B6: Antofagasta | C6: Sitio web | D6: 2023-02-27 | E6: Comisión de Salud y Medioambiente del Consejo Regional ante proyecto minero Comahue | F6: https://goreantofagasta.cl/comision-de-salud-y-medioambiente-del-consejo-regional-ante-proyecto/goreantofagasta/2023-02-27/093403.html | G6: Agenda 2030 | H6: Retórica | I6: Invoca la Agenda 2030 para justificar el diálogo entre proyectos y comunidades. | J6: Retórica | K6: =IF(J6="","",IF(J6=H6,1,0)) -> 1 | L6: Retórica
A7: W03 | B7: Atacama | C7: Sitio web | D7: 2019-08-27 | E7: Balance positivo del primer Festival Urbano de Sostenibilidad, Innovación y Territorio | F7: https://goreatacama.gob.cl/2019/08/27/balance-positivo-del-primer-festival-urbano-de-sostenibilidad-innovacion-y-territorio/ | G7: ODS, Objetivos de Desarrollo Sostenible | H7: Retórica | I7: Festival organizado por Corfo, Minvu y Gedes; menciona que las alianzas contribuyen a los ODS. | J7: Retórica | K7: =IF(J7="","",IF(J7=H7,1,0)) -> 1 | L7: Retórica
A8: W04 | B8: Coquimbo | C8: Sitio web | D8: s/f | E8: Gobernadora realizó cuenta pública sobre Cambio Climático destacando inversión para tomar acciones en esta materia | F8: https://www.gorecoquimbo.cl/noticias/gobernadora-realizo-cuenta-publica-sobre-cambio-climatico-destacando | G8: ODS, Objetivos de Desarrollo Sostenible | H8: Retórica | I8: Menciona «avanzar hacia el cumplimiento de los ODS» como propósito general, sin metas ni indicadores. | J8: Retórica | K8: =IF(J8="","",IF(J8=H8,1,0)) -> 1 | L8: Retórica
A9: W05 | B9: Coquimbo | C9: Sitio web | D9: s/f | E9: Celebran el Día Mundial del Turismo con un sello inclusivo y sustentable en la Región de Coquimbo | F9: https://www.gorecoquimbo.cl/noticias/celebran-el-dia-mundial-del-turismo-con-un-sello-inclusivo-y-sustentable-en | G9: Objetivos de Desarrollo Sostenible | H9: Retórica | I9: Referencia general a la contribución del turismo a los ODS. | J9: Retórica | K9: =IF(J9="","",IF(J9=H9,1,0)) -> 1 | L9: Retórica
A10: W06 | B10: Coquimbo | C10: Sitio web | D10: s/f | E10: Párvulos de Vicuña se manifiestan en «Yo opino, es mi derecho» | F10: https://www.gorecoquimbo.cl/noticias/parvulos-de-vicuna-se-manifiestan-en-yo-opino-es-mi-derecho | G10: Objetivos de Desarrollo Sostenible | H10: Retórica | I10: Programa de participación infantil sobre los 17 ODS (Mideso/PNUD); sin metas del GORE. | J10: Retórica | K10: =IF(J10="","",IF(J10=H10,1,0)) -> 1 | L10: Retórica
A11: W07 | B11: Coquimbo | C11: Sitio web | D11: s/f | E11: Comienzan debates de niños y adolescentes en tercera versión de «Yo opino, es mi derecho» | F11: https://www.gorecoquimbo.cl/noticias/comienzan-debates-de-ninos-y-adolescentes-en-tercera-version-de-yo-opino | G11: Objetivos de Desarrollo Sostenible | H11: Retórica | I11: Idem anterior. | J11: Retórica | K11: =IF(J11="","",IF(J11=H11,1,0)) -> 1 | L11: Retórica
A12: W08 | B12: Valparaíso | C12: Sitio web | D12: 2025-11-20 | E12: Gobierno Regional aprueba Plan Estratégico para la Gestión Integral de Residuos Sólidos Domiciliarios y Asimilables de la Región de Valparaíso | F12: https://www.gobiernovalparaiso.cl/detalleNoticia.php?idNot=NzAz | G12: Agenda 2030 | H12: Retórica | I12: El plan se declara «en coherencia» con la Agenda 2030 y la ERD 2025-2035; no vincula metas ni indicadores ODS. | J12: Retórica | K12: =IF(J12="","",IF(J12=H12,1,0)) -> 1 | L12: Retórica
A13: W09 | B13: Valparaíso | C13: Sitio web | D13: 2025-11-11 | E13: Gobierno Regional de Valparaíso y Cámara Chilena de la Construcción impulsan Consejo Regional de Sostenibilidad e Innovación para la Construcción | F13: https://www.gobiernovalparaiso.cl/detalleNoticia.php?idNot=Njk5 | G13: ODS, Objetivos de Desarrollo Sostenible | H13: Retórica | I13: «Reafirma su compromiso con los ODS»; declaración general. | J13: Retórica | K13: =IF(J13="","",IF(J13=H13,1,0)) -> 1 | L13: Retórica
A14: W10 | B14: Valparaíso | C14: Sitio web | D14: 2025-04-17 | E14: Finaliza agenda de trabajo de la delegación chilena en la ONU relacionada con la postulación de Valparaíso como sede del BBNJ | F14: https://www.gobiernovalparaiso.cl/detalleNoticia.php?idNot=NTk0 | G14: Agenda 2030 | H14: Retórica | I14: Referencia a la Agenda 2030 en actividad internacional. | J14: Retórica | K14: =IF(J14="","",IF(J14=H14,1,0)) -> 1 | L14: Retórica
A15: W11 | B15: Valparaíso | C15: Sitio web | D15: 2023-08-02 | E15: Gobernador Rodrigo Mundaca asume presidencia interina del Comité de Gestión Reserva de la Biósfera La Campana-Peñuelas | F15: https://www.gobiernovalparaiso.cl/detalleNoticia.php?idNot=MzQ5 | G15: Objetivos de Desarrollo Sostenible | H15: Retórica | I15: Mención genérica a «la mirada de la sostenibilidad y los ODS». | J15: Retórica | K15: =IF(J15="","",IF(J15=H15,1,0)) -> 1 | L15: Retórica
A16: W12 | B16: Valparaíso | C16: Sitio web | D16: 2023-07-24 | E16: Gobernador Rodrigo Mundaca visita sitios patrimoniales y se reúne con la comunidad de Rapa Nui | F16: https://www.gobiernovalparaiso.cl/detalleNoticia.php?idNot=MzQy | G16: Objetivos de Desarrollo Sostenible | H16: Retórica | I16: Cita del gobernador que enumera temas, entre ellos «objetivos de desarrollo sostenible». | J16: Retórica | K16: =IF(J16="","",IF(J16=H16,1,0)) -> 1 | L16: Retórica
... A36: W32 | B36: Magallanes | C36: Sitio web | D36: 2025-03-24 | E36: Con alta convocatoria de inversionistas nacionales y extranjeros se desarrolló el foro de inversiones en Punta Arenas | F36: https://www.goremagallanes.cl/con-alta-convocatoria-de-inversionistas-nacionales-y-extranjeros-se-desarrollo-el-foro-de-inversiones-en-punta-arenas/ | G36: Objetivos de Desarrollo Sostenible | H36: Retórica | I36: Menciona los ODS como antecedente general del foro. | J36: Retórica | K36: =IF(J36="","",IF(J36=H36,1,0)) -> 1 | L36: Retórica
A37: D01 | B37: Antofagasta | C37: Cuenta pública | D37: p. 46 | E37: Cuenta Pública Gobierno Regional 2024 (publicada 04-02-2026) | F37: https://goreantofagasta.cl/goreantofagasta/site/artic/20260204/asocfile/20260204211006/cuenta_publica_2024.pdf | H37: Retórica | I37: Minería más sustentable «en línea con los Objetivos de Desarrollo Sostenible de las Naciones Unidas». | J37: Retórica | K37: =IF(J37="","",IF(J37=H37,1,0)) -> 1 | L37: Retórica
A38: D02 | B38: Atacama | C38: ERD | D38: p. 20 | E38: ERDA 2024-2034 | F38: https://www.goreatacama.gob.cl (2024_08_01_ERDA_2024_2034_VERSION_INAL.pdf) | H38: Retórica | I38: «Estos lineamientos son consistentes con los ODS de la Agenda 2030» | J38: Retórica | K38: =IF(J38="","",IF(J38=H38,1,0)) -> 1 | L38: Retórica
A39: D03 | B39: Coquimbo | C39: ERD | D39: p. 33 | E39: Estrategia Regional de Desarrollo 2030 (libro, nov. 2025) | F39: https://www.gorecoquimbo.cl/gore/site/docs/20251128/20251128143713/libro_erd2030.pdf | H39: Sustantiva | I39: Cada desafío regional se relaciona con «los Objetivos de Desarrollo Sostenible de la Agenda 2030» (Figura 8). | J39: Sustantiva | K39: =IF(J39="","",IF(J39=H39,1,0)) -> 1 | L39: Sustantiva
A40: D04 | B40: Coquimbo | C40: ERD | D40: p. 37 | E40: Estrategia Regional de Desarrollo 2030 (libro, nov. 2025) | F40: https://www.gorecoquimbo.cl/gore/site/docs/20251128/20251128143713/libro_erd2030.pdf | H40: Sustantiva | I40: «Este planteamiento se relaciona con cuatro ODS: (3)… (4)… (6)… (7)» | J40: Sustantiva | K40: =IF(J40="","",IF(J40=H40,1,0)) -> 1 | L40: Sustantiva
A41: D05 | B41: Coquimbo | C41: ERD | D41: p. 42 | E41: Estrategia Regional de Desarrollo 2030 (libro, nov. 2025) | F41: https://www.gorecoquimbo.cl/gore/site/docs/20251128/20251128143713/libro_erd2030.pdf | H41: Sustantiva | I41: Vivienda vinculada al ODS 11 y a su primera meta (acceso a vivienda). | J41: Sustantiva | K41: =IF(J41="","",IF(J41=H41,1,0)) -> 1 | L41: Sustantiva
A42: D06 | B42: Valparaíso | C42: ERD | D42: p. 81 | E42: Estrategia Regional de Desarrollo 2025-2035 | F42: https://www.gobiernovalparaiso.cl/administracion/archivo/archivoDocumento/general/ESTRATEGIA_REGIONAL_DE_DESARROLLO_2025_2035.pdf | H42: Sustantiva | I42: La matriz estratégica se alinea con «los objetivos del desarrollo sostenible de la agenda 2030». | J42: Sustantiva | K42: =IF(J42="","",IF(J42=H42,1,0)) -> 1 | L42: Sustantiva
A43: D07 | B43: Valparaíso | C43: ERD | D43: p. 88 | E43: Estrategia Regional de Desarrollo 2025-2035 | F43: https://www.gobiernovalparaiso.cl/administracion/archivo/archivoDocumento/general/ESTRATEGIA_REGIONAL_DE_DESARROLLO_2025_2035.pdf | H43: Sustantiva | I43: «las líneas de acción de este eje… contribuyen al logro de los siguientes Objetivos de Desarrollo Sostenible: … (ODS 01)… (ODS 10)»; patrón repetido por eje (pp. 92, 96, 104, 108). | J43: Sustantiva | K43: =IF(J43="","",IF(J43=H43,1,0)) -> 1 | L43: Sustantiva
A44: D08 | B44: Metropolitana | C44: ERD | D44: p. 56 | E44: ERD RM 2035 | F44: https://gobiernosantiago.cl/wp-content/uploads/2026/06/ERD-RM_2035.pdf | H44: Sustantiva | I44: Figura 17: matriz que vincula los lineamientos L1–L7 de la ERD RM 2035 con ODS específicos (p. ej., L7 Gobernanza multinivel ↔ ODS 16). | J44: Sustantiva | K44: =IF(J44="","",IF(J44=H44,1,0)) -> 1 | L44: Sustantiva
A45: D09 | B45: Metropolitana | C45: ERD | D45: p. 57 | E45: ERD RM 2035 | F45: https://gobiernosantiago.cl/wp-content/uploads/2026/06/ERD-RM_2035.pdf | H45: Sustantiva | I45: «los siete lineamientos estratégicos comprometen al menos un ODS» | J45: Sustantiva | K45: =IF(J45="","",IF(J45=H45,1,0)) -> 1 | L45: Sustantiva
A46: D10 | B46: Maule | C46: ERD | D46: p. 9 | E46: ERD Maule 2042 – Documento Consolidado (13-04-2023) | F46: https://www.goremaule.cl/goremauleVII/wp-content/uploads/2023/04/Documento-Consolidado-de-la-ERD-Maule-2042.pdf | H46: Sustantiva | I46: «Si bien los ODS son el marco a partir del cual se estructura la Estrategia Regional de Desarrollo Maule 2042…» | J46: Sustantiva | K46: =IF(J46="","",IF(J46=H46,1,0)) -> 1 | L46: Sustantiva
A47: D11 | B47: Maule | C47: ERD | D47: p. 13 | E47: ERD Maule 2042 – Documento Consolidado (13-04-2023) | F47: https://www.goremaule.cl/goremauleVII/wp-content/uploads/2023/04/Documento-Consolidado-de-la-ERD-Maule-2042.pdf | H47: Sustantiva | I47: Cada lineamiento, objetivo y acción establece su «alineamiento con los Objetivos de Desarrollo Sostenible y las metas de la Agenda 2030». | J47: Sustantiva | K47: =IF(J47="","",IF(J47=H47,1,0)) -> 1 | L47: Sustantiva
A48: D12 | B48: Maule | C48: ERD | D48: p. 61 | E48: ERD Maule 2042 – Documento Consolidado (13-04-2023) | F48: https://www.goremaule.cl/goremauleVII/wp-content/uploads/2023/04/Documento-Consolidado-de-la-ERD-Maule-2042.pdf | H48: Retórica | I48: Sección 3.2 «La importancia de los valores de la ONU y la Agenda 2030»; ilustración de los 17 ODS. | J48: Sustantiva | K48: =IF(J48="","",IF(J48=H48,1,0)) -> 0 | L48: Retórica
A49: D13 | B49: La Araucanía | C49: ERD | D49: p. 8 | E49: Estrategia Regional de Desarrollo Araucanía 2040 (ERD 2025-2040) | F49: https://drive.google.com/file/d/1M8MSDkl266PpgDlU2LiIdMtbJCA0IPwJ/view | G49: ODS, Objetivos de Desarrollo Sostenible | H49: Retórica | I49: Alineación con compromisos «nacionales y globales, tales como los Objetivos de Desarrollo Sostenible (ODS)». | J49: Retórica | K49: =IF(J49="","",IF(J49=H49,1,0)) -> 1 | L49: Retórica
A50: D14 | B50: La Araucanía | C50: ERD | D50: p. 120 | E50: Estrategia Regional de Desarrollo Araucanía 2040 (ERD 2025-2040) | F50: https://drive.google.com/file/d/1M8MSDkl266PpgDlU2LiIdMtbJCA0IPwJ/view | G50: ODS, Objetivos de Desarrollo Sostenible | H50: Sustantiva | I50: Figura 44: vincula cada uno de los 17 ODS con un Lineamiento Estratégico Regional (LER 1–6); ODS 16 ↔ LER 4 «Institucionalidad, gobernanza y participación». | J50: Sustantiva | K50: =IF(J50="","",IF(J50=H50,1,0)) -> 1 | L50: Sustantiva
A51: D15 | B51: Los Lagos | C51: ERD | D51: p. 70 | E51: Estrategia Regional de Desarrollo Los Lagos 2030 | F51: https://goreloslagos.cl/storage/web/pages/documents/01KJ2Y01G6FFAW58G8EJB2WGPG.pdf | G51: ODS, Objetivos de Desarrollo Sostenible | H51: Retórica | I51: Los temas de la ERD «se relacionan con macro objetivos de escala global […] tales como los ODS»; sin vinculación por objetivo ni indicadores. | J51: Sustantiva | K51: =IF(J51="","",IF(J51=H51,1,0)) -> 0 | L51: Retórica
A52: D16 | B52: Magallanes | C52: ERD | D52: p. 35 | E52: Estrategia Regional de Desarrollo 2023-2030 (aprobada por el CORE el 16-05-2023) | F52: https://www.goremagallanes.cl/wp-content/uploads/2025/09/Estrategia-Regional-de-Desarrollo-2023-2030.pdf | G52: ODS, Objetivos de Desarrollo Sostenible | H52: Sustantiva | I52: La ERD asume la Agenda 2030 como marco transversal y declara que «cada objetivo de la ERD se relaciona con uno o más de los 17 ODS». | J52: Sustantiva | K52: =IF(J52="","",IF(J52=H52,1,0)) -> 1 | L52: Sustantiva
I54: Acuerdo observado en tipo (ítems con 2.ª codificación): | K54: =IFERROR(AVERAGE(K5:K52),"") -> 0.9375
I55: Acuerdo esperado por azar (pe): | K55: =IFERROR((COUNTIFS(H5:H52,"Retórica",J5:J52,"?*")/COUNTIF(J5:J52,"?*"))*(COUNTIF(J5:J52,"Retórica")/COUNTIF(J5:J52,"?*"))+(COUNTIFS(H5:H52,"Sustantiva",J5:J52,"?*")/COUNTIF(J5:J52,"?*"))*(COUNTIF(J5:J52,"Sustantiva")/COUNTIF(J5:J52,"?*")),"") -> 0.50868056
I56: κ de Cohen (tipo de mención): | K56: =IFERROR((K54-K55)/(1-K55),"") -> 0.87279152

Sheet Documentos
A1: Registro de documentos (fuentes 2 y 3: cuenta pública y ERD)
A2: Conteos por término sobre el texto extraído del PDF. Vacío = documento no disponible o no procesable.
A4: GORE | B4: Fuente | C4: Documento | D4: URL | E4: Páginas | F4: Caracteres | G4: Car./pág. | H4: ODS | I4: Objetivos de Desarrollo Sostenible | J4: Agenda 2030 | K4: ODS 16 | L4: desarrollo sostenible | M4: sostenibilidad | N4: Naciones Unidas | O4: Clasificación | P4: Nota | Q4: Fecha | R4: Codificador
A5: Arica y Parinacota | B5: Cuenta pública | C5: Documento técnico Cuenta Pública GORE Arica y Parinacota 2025-2026 | D5: https://www.gorearicayparinacota.cl/goreayp/site/docs/20260309/20260309134718/cuentapublica2025.pdf | E5: 91 | F5: 253722 | G5: =IF(OR(E5="",F5=""),"",ROUND(F5/E5,0)) -> 2788 | H5: 0 | I5: 0 | J5: 0 | K5: 0 | L5: 1 | M5: 16 | N5: 0 | O5: Sin mención | Q5: 2026-09-23 | R5: scraping e IA
A6: Arica y Parinacota | B6: ERD | C6: ERD Arica y Parinacota 2017-2030 (sitio web anterior del GORE) | G6: =IF(OR(E6="",F6=""),"",ROUND(F6/E6,0)) | O6: Sustantiva | P6: Búsqueda dirigida 28-09: solo en el sitio web anterior del GORE. p. 165: «se seleccionó un grupo de metas de los ODS que poseen indicadores»; metas del ODS 16 (16.1-16.6, 16.9, 16.b). Conteos por término pendientes. | Q6: 2026-09-28 | R6: scraping e IA
A7: Tarapacá | B7: Cuenta pública | C7: Cuenta Pública GORE 2025 («#GobernandoDesdeLosTerritorios») | D7: https://www.goretarapaca.gov.cl/wp-content/uploads/2026/05/CUENTA-PUBLICA-GORE-2025-1.pdf | E7: 145 | F7: 150316 | G7: =IF(OR(E7="",F7=""),"",ROUND(F7/E7,0)) -> 1037 | H7: 0 | I7: 0 | J7: 0 | K7: 0 | L7: 0 | M7: 5 | N7: 0 | O7: Sin mención | Q7: 2026-09-23 | R7: scraping e IA
A8: Tarapacá | B8: ERD | C8: Actualización de la Estrategia Regional de Desarrollo, Región de Tarapacá 2023-2033 (documento final) | D8: https://www.goretarapaca.gov.cl/wp-content/uploads/2024/04/Documento-ERD-Tarapaca%CC%81-2023_vf.pdf | E8: 98 | F8: 183204 | G8: =IF(OR(E8="",F8=""),"",ROUND(F8/E8,0)) -> 1869 | H8: 0 | I8: 0 | J8: 0 | K8: 0 | L8: 0 | M8: 3 | N8: 1 | O8: Sin mención | Q8: 2026-09-23 | R8: scraping e IA
A9: Antofagasta | B9: Cuenta pública | C9: Cuenta Pública Gobierno Regional 2024 (publicada 04-02-2026) | D9: https://goreantofagasta.cl/goreantofagasta/site/artic/20260204/asocfile/20260204211006/cuenta_publica_2024.pdf | E9: 62 | F9: 26034 | G9: =IF(OR(E9="",F9=""),"",ROUND(F9/E9,0)) -> 420 | H9: 0 | I9: 1 | J9: 0 | K9: 0 | L9: 3 | M9: 0 | N9: 2 | O9: Retórica | P9: No hay cuenta pública más reciente publicada. | Q9: 2026-09-23 | R9: scraping e IA
A10: Antofagasta | B10: ERD | C10: Estrategia Regional de Desarrollo 2009-2020 (única publicada) | D10: https://goreantofagasta.cl/goreantofagasta/site/artic/20161006/asocfile/20161006170042/estrategia_2009_2020.pdf | E10: 120 | F10: 121931 | G10: =IF(OR(E10="",F10=""),"",ROUND(F10/E10,0)) -> 1016 | H10: 0 | I10: 0 | J10: 0 | K10: 0 | L10: 2 | M10: 0 | N10: 1 | O10: Sin mención | P10: ERD vencida, anterior a la Agenda 2030 (2015). | Q10: 2026-09-23 | R10: scraping e IA
A11: Atacama | B11: Cuenta pública | C11: Cuenta Pública 2026 | D11: https://www.goreatacama.gob.cl (2026_05_28_Cuenta_Publica_2026.pdf) | E11: 99 | F11: 262736 | G11: =IF(OR(E11="",F11=""),"",ROUND(F11/E11,0)) -> 2654 | H11: 0 | I11: 0 | J11: 0 | K11: 0 | L11: 11 | M11: 32 | N11: 0 | O11: Sin mención | P11: 0 menciones de términos núcleo. | Q11: 2026-09-23 | R11: scraping e IA
A12: Atacama | B12: ERD | C12: ERDA 2024-2034 | D12: https://www.goreatacama.gob.cl (2024_08_01_ERDA_2024_2034_VERSION_INAL.pdf) | E12: 91 | F12: 256230 | G12: =IF(OR(E12="",F12=""),"",ROUND(F12/E12,0)) -> 2816 | H12: 1 | I12: 1 | J12: 1 | K12: 0 | L12: 27 | M12: 22 | N12: 2 | O12: Retórica | P12: Declaración general de consistencia, sin vincular metas ni indicadores. | Q12: 2026-09-23 | R12: scraping e IA
A13: Coquimbo | B13: Cuenta pública | C13: Cuenta Pública Gestión 2025 | D13: https://www.gorecoquimbo.cl/CP2025/Cuenta_Publica_Gestion_2025.pdf | E13: 39 | F13: 20344 | G13: =IF(OR(E13="",F13=""),"",ROUND(F13/E13,0)) -> 522 | H13: 0 | I13: 0 | J13: 0 | K13: 0 | L13: 0 | M13: 0 | N13: 0 | O13: Sin mención | P13: Formato presentación (≈520 caracteres/página). | Q13: 2026-09-23 | R13: scraping e IA
A14: Coquimbo | B14: ERD | C14: Estrategia Regional de Desarrollo 2030 (libro, nov. 2025) | D14: https://www.gorecoquimbo.cl/gore/site/docs/20251128/20251128143713/libro_erd2030.pdf | E14: 168 | F14: 264030 | G14: =IF(OR(E14="",F14=""),"",ROUND(F14/E14,0)) -> 1572 | H14: 14 | I14: 5 | J14: 4 | K14: 0 | L14: 12 | M14: 4 | N14: 3 | O14: Sustantiva | P14: Vinculación desafío/lineamiento–ODS con referencia a metas. | Q14: 2026-09-23 | R14: scraping e IA
A15: Valparaíso | B15: Cuenta pública | C15: Cuenta Pública 2026 ante el Consejo Regional | D15: https://www.gobiernovalparaiso.cl/administracion/archivo/archivoDocumento/2026/documento20260529103401.pdf | E15: 49 | F15: 24408 | G15: =IF(OR(E15="",F15=""),"",ROUND(F15/E15,0)) -> 498 | H15: 0 | I15: 0 | J15: 0 | K15: 0 | L15: 0 | M15: 0 | N15: 0 | O15: Sin mención | P15: Formato presentación. | Q15: 2026-09-23 | R15: scraping e IA
A16: Valparaíso | B16: ERD | C16: Estrategia Regional de Desarrollo 2025-2035 | D16: https://www.gobiernovalparaiso.cl/administracion/archivo/archivoDocumento/general/ESTRATEGIA_REGIONAL_DE_DESARROLLO_2025_2035.pdf | E16: 148 | F16: 237359 | G16: =IF(OR(E16="",F16=""),"",ROUND(F16/E16,0)) -> 1604 | H16: 14 | I16: 7 | J16: 2 | K16: 1 | L16: 22 | M16: 13 | N16: 5 | O16: Sustantiva | P16: Cada eje declara los ODS a los que contribuye. | Q16: 2026-09-23 | R16: scraping e IA
A17: Metropolitana | B17: Cuenta pública | C17: Cuenta Pública Gobierno de Santiago 2026 | D17: https://gobiernosantiago.cl/wp-content/uploads/2026/05/Cuenta-Pu%CC%81blica-Gobierno-de-Santiago-2026.pdf | E17: 45 | F17: 127239 | G17: =IF(OR(E17="",F17=""),"",ROUND(F17/E17,0)) -> 2828 | H17: 0 | I17: 0 | J17: 0 | K17: 0 | L17: 1 | M17: 9 | N17: 2 | O17: Sin mención | P17: 0 menciones núcleo. Sitio bloquea pdf.js (CSP); PDF transferido completo y verificado por tamaño (1.349.203 bytes). | Q17: 2026-09-23 | R17: scraping e IA
A18: Metropolitana | B18: ERD | C18: ERD RM 2035 | D18: https://gobiernosantiago.cl/wp-content/uploads/2026/06/ERD-RM_2035.pdf | E18: 79 | F18: 260567 | G18: =IF(OR(E18="",F18=""),"",ROUND(F18/E18,0)) -> 3298 | H18: 12 | I18: 2 | J18: 0 | K18: 1 | L18: 8 | M18: 16 | N18: 1 | O18: Sustantiva | P18: Vinculación explícita lineamiento–ODS (incluye ODS 16); sin metas ni indicadores ODS. | Q18: 2026-09-23 | R18: scraping e IA
A19: O'Higgins | B19: Cuenta pública | C19: Cuenta Pública Gobierno Regional de O'Higgins, enero a diciembre 2025 | D19: https://www.goreohiggins.cl/cuentapublica/CuentaPublica2025_v2.pdf | E19: 63 | F19: 174496 | G19: =IF(OR(E19="",F19=""),"",ROUND(F19/E19,0)) -> 2770 | H19: 0 | I19: 0 | J19: 0 | K19: 0 | L19: 1 | M19: 12 | N19: 0 | O19: Sin mención | Q19: 2026-09-23 | R19: scraping e IA
A20: O'Higgins | B20: ERD | C20: ERD O'Higgins (ruta no enlazada desde la página de la ERD) | D20: https://www.goreohiggins.cl/docs/diplade/estrategias_regionales.zip | G20: =IF(OR(E20="",F20=""),"",ROUND(F20/E20,0)) | O20: Sin mención | P20: Búsqueda dirigida 28-09: la página de la ERD solo ofrecía un .zip; el PDF estaba en una ruta no enlazada. Conteos por término pendientes. | Q20: 2026-09-28 | R20: scraping e IA
A21: Maule | B21: Cuenta pública | C21: Cuenta Pública 2025 | D21: https://www.goremaule.cl (Cuenta Pública 2025, PDF) | E21: 90 | F21: 209349 | G21: =IF(OR(E21="",F21=""),"",ROUND(F21/E21,0)) -> 2326 | H21: 0 | I21: 0 | J21: 0 | K21: 0 | L21: 5 | M21: 27 | N21: 0 | O21: Sin mención | P21: 0 menciones de términos núcleo. | Q21: 2026-09-23 | R21: scraping e IA
A22: Maule | B22: ERD | C22: ERD Maule 2042 – Documento Consolidado (13-04-2023) | D22: https://www.goremaule.cl/goremauleVII/wp-content/uploads/2023/04/Documento-Consolidado-de-la-ERD-Maule-2042.pdf | E22: 186 | F22: 617891 | G22: =IF(OR(E22="",F22=""),"",ROUND(F22/E22,0)) -> 3322 | H22: 22 | I22: 13 | J22: 34 | K22: 0 | L22: 36 | M22: 24 | N22: 8 | O22: Sustantiva | P22: La ERD declara los ODS como marco estructurante y alinea lineamientos/objetivos/acciones con ODS y metas. El PDF principal (Estrategia-Regional-de-Desarrollo-Maule-2042-1-1.pdf, 281 pp) es escaneado (0 caracteres); se usó el Documento Consolidado. Informe Ejecutivo (97 pp): ODS 4, ODSos 7, Agenda 2030 10. | Q22: 2026-09-23 | R22: scraping e IA
A23: Ñuble | B23: Cuenta pública | C23: Cuenta Pública 2026 («Cambiamos la vida de las personas») | D23: https://goredenuble.cl/wp-content/uploads/2026/05/cuenta-2026-final-22.pdf | E23: 68 | F23: 64851 | G23: =IF(OR(E23="",F23=""),"",ROUND(F23/E23,0)) -> 954 | H23: 0 | I23: 0 | J23: 0 | K23: 0 | L23: 1 | M23: 2 | N23: 0 | O23: Sin mención | Q23: 2026-09-23 | R23: scraping e IA
A24: Ñuble | B24: ERD | C24: Estrategia Regional de Desarrollo de Ñuble 2030 (documento de ajuste, 24 pp.) | D24: https://goredenuble.cl/wp-content/uploads/2024/01/ERD-FINAL.pdf | E24: 24 | F24: 22578 | G24: =IF(OR(E24="",F24=""),"",ROUND(F24/E24,0)) -> 941 | H24: 0 | I24: 0 | J24: 0 | K24: 0 | L24: 0 | M24: 0 | N24: 0 | O24: Sin mención | Q24: 2026-09-23 | R24: scraping e IA
A25: Biobío | B25: Cuenta pública | C25: Cuenta Pública Biobío 2026 (presentación enlazada desde un banner) | D25: https://gorebiobio.cl/sesionescore/sesion-extraordinaria-no-4-2026-cuenta-publica-gobernador-regional/ | G25: =IF(OR(E25="",F25=""),"",ROUND(F25/E25,0)) | O25: No disponible | P25: Revisión 29-09: la cuenta pública 2025 se publicó solo en video (YouTube); se excluye como documento. | Q25: 2026-09-28 | R25: scraping e IA
A26: Biobío | B26: ERD | C26: ERD Biobío 2015-2030 | D26: https://www.gorebiobio.cl (ERD 2015-2030, PDF) | E26: 31 | F26: 39350 | G26: =IF(OR(E26="",F26=""),"",ROUND(F26/E26,0)) -> 1269 | H26: 0 | I26: 0 | J26: 0 | K26: 0 | L26: 0 | M26: 0 | N26: 0 | O26: Sin mención | P26: Sin menciones de ningún término. | Q26: 2026-09-23 | R26: scraping e IA
A27: Biobío | B27: ERD | C27: Ajuste ERD Región del Biobío (junio 2023, presentación) | D27: https://www.gorebiobio.cl (Ajuste ERD, PDF) | E27: 13 | F27: 14438 | G27: =IF(OR(E27="",F27=""),"",ROUND(F27/E27,0)) -> 1111 | H27: 0 | I27: 0 | J27: 0 | K27: 0 | L27: 4 | M27: 4 | N27: 0 | O27: Sin mención | P27: 0 menciones núcleo. | Q27: 2026-09-23 | R27: scraping e IA
A28: La Araucanía | B28: Cuenta pública | C28: Cuenta Pública 2025 (visor Heyzine en gorearaucania.cl/cuentas-publicas) | D28: https://gorearaucania.cl/cuentas-publicas | E28: 70 | F28: 95923 | G28: =IF(OR(E28="",F28=""),"",ROUND(F28/E28,0)) -> 1370 | H28: 0 | I28: 0 | J28: 0 | K28: 0 | L28: 4 | M28: 3 | N28: 0 | O28: Sin mención | P28: Revisión 07-10-2026: documento en visor embebido Heyzine (PDF original obtenido desde el visor). Sin términos ODS núcleo; solo términos de contexto. | Q28: 2026-10-07 | R28: scraping e IA
A29: La Araucanía | B29: ERD | C29: Estrategia Regional de Desarrollo Araucanía 2040 (ERD 2025-2040) | D29: https://drive.google.com/file/d/1M8MSDkl266PpgDlU2LiIdMtbJCA0IPwJ/view | E29: 218 | F29: 358550 | G29: =IF(OR(E29="",F29=""),"",ROUND(F29/E29,0)) -> 1645 | H29: 3 | I29: 1 | J29: 0 | K29: 0 | L29: 11 | M29: 12 | N29: 1 | O29: Sustantiva | P29: PDF alojado en Google Drive, descargado por la cod. 2 (24-09-2026). Vinculación ODS–lineamientos en la Figura 44 (p. 120). | Q29: 2026-09-23 | R29: scraping e IA
A30: Los Ríos | B30: Cuenta pública | C30: Discurso Cuenta Pública 2025 | D30: https://www.goredelosrios.cl/wp-content/uploads/2026/06/Discurso-Cuenta-Publica-2025-Gobierno-Regional-de-Los-Rios-1.pdf | E30: 31 | F30: 70435 | G30: =IF(OR(E30="",F30=""),"",ROUND(F30/E30,0)) -> 2272 | H30: 0 | I30: 0 | J30: 0 | K30: 0 | L30: 1 | M30: 2 | N30: 1 | O30: Sin mención | Q30: 2026-09-23 | R30: scraping e IA
A31: Los Ríos | B31: ERD | C31: ERD Los Ríos 2023-2037 (sitio propio erdlosrios.cl) | D31: https://www.goredelosrios.cl | G31: =IF(OR(E31="",F31=""),"",ROUND(F31/E31,0)) | O31: Retórica | P31: Búsqueda dirigida 28-09. p. 84: los ODS solo aparecen dentro de una cita de la UNESCO (declarativa). Conteos por término pendientes. | Q31: 2026-09-28 | R31: scraping e IA
A32: Los Lagos | B32: Cuenta pública | C32: No localizada: la sección «Documentos de gestión» (89 PDF revisados) no contiene la cuenta pública | G32: =IF(OR(E32="",F32=""),"",ROUND(F32/E32,0)) | O32: No disponible | P32: Revisión 29-09: la cuenta pública 2025 se publicó solo en video (YouTube). | Q32: 2026-09-23 | R32: scraping e IA
A33: Los Lagos | B33: ERD | C33: Estrategia Regional de Desarrollo Los Lagos 2030 | D33: https://goreloslagos.cl/storage/web/pages/documents/01KJ2Y01G6FFAW58G8EJB2WGPG.pdf | E33: 186 | F33: 247802 | G33: =IF(OR(E33="",F33=""),"",ROUND(F33/E33,0)) -> 1332 | H33: 1 | I33: 1 | J33: 0 | K33: 0 | L33: 1 | M33: 0 | N33: 0 | O33: Retórica | Q33: 2026-09-23 | R33: scraping e IA
A34: Aysén | B34: Cuenta pública | C34: Cuenta Pública 28 de mayo 2026 | D34: https://www.goreaysen.cl/wp-content/uploads/2026/06/CuentaPublica_28_MAYO.pdf | E34: 66 | F34: 8724 | G34: =IF(OR(E34="",F34=""),"",ROUND(F34/E34,0)) -> 132 | H34: 0 | I34: 0 | J34: 0 | K34: 0 | L34: 0 | M34: 0 | N34: 0 | O34: Sin mención | P34: Presentación fotográfica (66 láminas con títulos). Revisada con OCR (tesseract) el 24-09-2026: sin términos ODS ni de contexto. | Q34: 2026-09-23 | R34: scraping e IA
A35: Aysén | B35: ERD | C35: ERD Aysén («Documentación de interés», nombre de archivo poco identificable) | D35: https://www.goreaysen.cl/documentacion-de-interes/ | G35: =IF(OR(E35="",F35=""),"",ROUND(F35/E35,0)) | O35: Sin mención | P35: Búsqueda dirigida 28-09. Conteos por término pendientes. | Q35: 2026-09-28 | R35: scraping e IA
A36: Magallanes | B36: Cuenta pública | C36: Cuenta Pública 2026 (gestión 2025) | D36: https://www.goremagallanes.cl/wp-content/uploads/2026/07/Cuenta-2026_219_ENTREGA-GORE_Final.pdf | E36: 148 | F36: 31775 | G36: =IF(OR(E36="",F36=""),"",ROUND(F36/E36,0)) -> 215 | H36: 0 | I36: 0 | J36: 0 | K36: 0 | L36: 1 | M36: 1 | N36: 0 | O36: Sin mención | P36: Documento mayoritariamente en imágenes; revisado con OCR (tesseract, 148 pp., 24-09-2026): sin términos ODS núcleo (1 «desarrollo sostenible», 1 «sostenibilidad»). | Q36: 2026-09-23 | R36: scraping e IA
A37: Magallanes | B37: ERD | C37: Estrategia Regional de Desarrollo 2023-2030 (aprobada por el CORE el 16-05-2023) | D37: https://www.goremagallanes.cl/wp-content/uploads/2025/09/Estrategia-Regional-de-Desarrollo-2023-2030.pdf | E37: 90 | F37: 353425 | G37: =IF(OR(E37="",F37=""),"",ROUND(F37/E37,0)) -> 3927 | H37: 2 | I37: 1 | J37: 0 | K37: 0 | L37: 5 | M37: 9 | N37: 4 | O37: Sustantiva | P37: Revisión 25-09-2026 (versión de alta resolución, 49 MB, mismo texto): 58 tablas de indicadores con columna «ODS» en versalitas (el texto extraído dice «ods»); por la regla de mayúsculas esos encabezados no se cuentan como mención. Los 17 ODS aparecen asignados a indicadores; ODS 16 en 4. | Q37: 2026-09-23 | R37: scraping e IA

Sheet Resumen_GORE
A1: Tabla corta: menciones ODS por GORE y por tipo
A2: Todo calculado con fórmulas desde «Menciones» y «Documentos».
A4: GORE | B4: Web: retóricas | C4: Web: sustantivas | D4: Web: total | E4: Cuenta pública | F4: ERD | G4: Algún vínculo sustantivo
A5: Arica y Parinacota | B5: =COUNTIFS(Menciones!$B$5:$B$52,A5,Menciones!$C$5:$C$52,"Sitio web",Menciones!$H$5:$H$52,"Retórica") -> 0 | C5: =COUNTIFS(Menciones!$B$5:$B$52,A5,Menciones!$C$5:$C$52,"Sitio web",Menciones!$H$5:$H$52,"Sustantiva") -> 0 | D5: =B5+C5 -> 0 | E5: Sin mención | F5: Sustantiva | G5: =IF(OR(C5>0,E5="Sustantiva",F5="Sustantiva"),"Sí","No") -> Sí
A6: Tarapacá | B6: =COUNTIFS(Menciones!$B$5:$B$52,A6,Menciones!$C$5:$C$52,"Sitio web",Menciones!$H$5:$H$52,"Retórica") -> 1 | C6: =COUNTIFS(Menciones!$B$5:$B$52,A6,Menciones!$C$5:$C$52,"Sitio web",Menciones!$H$5:$H$52,"Sustantiva") -> 0 | D6: =B6+C6 -> 1 | E6: Sin mención | F6: Sin mención | G6: =IF(OR(C6>0,E6="Sustantiva",F6="Sustantiva"),"Sí","No") -> No
A7: Antofagasta | B7: =COUNTIFS(Menciones!$B$5:$B$52,A7,Menciones!$C$5:$C$52,"Sitio web",Menciones!$H$5:$H$52,"Retórica") -> 1 | C7: =COUNTIFS(Menciones!$B$5:$B$52,A7,Menciones!$C$5:$C$52,"Sitio web",Menciones!$H$5:$H$52,"Sustantiva") -> 0 | D7: =B7+C7 -> 1 | E7: Retórica | F7: Sin mención | G7: =IF(OR(C7>0,E7="Sustantiva",F7="Sustantiva"),"Sí","No") -> No
A8: Atacama | B8: =COUNTIFS(Menciones!$B$5:$B$52,A8,Menciones!$C$5:$C$52,"Sitio web",Menciones!$H$5:$H$52,"Retórica") -> 1 | C8: =COUNTIFS(Menciones!$B$5:$B$52,A8,Menciones!$C$5:$C$52,"Sitio web",Menciones!$H$5:$H$52,"Sustantiva") -> 0 | D8: =B8+C8 -> 1 | E8: Sin mención | F8: Retórica | G8: =IF(OR(C8>0,E8="Sustantiva",F8="Sustantiva"),"Sí","No") -> No
A9: Coquimbo | B9: =COUNTIFS(Menciones!$B$5:$B$52,A9,Menciones!$C$5:$C$52,"Sitio web",Menciones!$H$5:$H$52,"Retórica") -> 4 | C9: =COUNTIFS(Menciones!$B$5:$B$52,A9,Menciones!$C$5:$C$52,"Sitio web",Menciones!$H$5:$H$52,"Sustantiva") -> 0 | D9: =B9+C9 -> 4 | E9: Sin mención | F9: Sustantiva | G9: =IF(OR(C9>0,E9="Sustantiva",F9="Sustantiva"),"Sí","No") -> Sí
A10: Valparaíso | B10: =COUNTIFS(Menciones!$B$5:$B$52,A10,Menciones!$C$5:$C$52,"Sitio web",Menciones!$H$5:$H$52,"Retórica") -> 7 | C10: =COUNTIFS(Menciones!$B$5:$B$52,A10,Menciones!$C$5:$C$52,"Sitio web",Menciones!$H$5:$H$52,"Sustantiva") -> 0 | D10: =B10+C10 -> 7 | E10: Sin mención | F10: Sustantiva | G10: =IF(OR(C10>0,E10="Sustantiva",F10="Sustantiva"),"Sí","No") -> Sí
A11: Metropolitana | B11: =COUNTIFS(Menciones!$B$5:$B$52,A11,Menciones!$C$5:$C$52,"Sitio web",Menciones!$H$5:$H$52,"Retórica") -> 2 | C11: =COUNTIFS(Menciones!$B$5:$B$52,A11,Menciones!$C$5:$C$52,"Sitio web",Menciones!$H$5:$H$52,"Sustantiva") -> 0 | D11: =B11+C11 -> 2 | E11: Sin mención | F11: Sustantiva | G11: =IF(OR(C11>0,E11="Sustantiva",F11="Sustantiva"),"Sí","No") -> Sí
A12: O'Higgins | B12: =COUNTIFS(Menciones!$B$5:$B$52,A12,Menciones!$C$5:$C$52,"Sitio web",Menciones!$H$5:$H$52,"Retórica") -> 0 | C12: =COUNTIFS(Menciones!$B$5:$B$52,A12,Menciones!$C$5:$C$52,"Sitio web",Menciones!$H$5:$H$52,"Sustantiva") -> 0 | D12: =B12+C12 -> 0 | E12: Sin mención | F12: Sin mención | G12: =IF(OR(C12>0,E12="Sustantiva",F12="Sustantiva"),"Sí","No") -> No
A13: Maule | B13: =COUNTIFS(Menciones!$B$5:$B$52,A13,Menciones!$C$5:$C$52,"Sitio web",Menciones!$H$5:$H$52,"Retórica") -> 2 | C13: =COUNTIFS(Menciones!$B$5:$B$52,A13,Menciones!$C$5:$C$52,"Sitio web",Menciones!$H$5:$H$52,"Sustantiva") -> 0 | D13: =B13+C13 -> 2 | E13: Sin mención | F13: Sustantiva | G13: =IF(OR(C13>0,E13="Sustantiva",F13="Sustantiva"),"Sí","No") -> Sí
A14: Ñuble | B14: =COUNTIFS(Menciones!$B$5:$B$52,A14,Menciones!$C$5:$C$52,"Sitio web",Menciones!$H$5:$H$52,"Retórica") -> 0 | C14: =COUNTIFS(Menciones!$B$5:$B$52,A14,Menciones!$C$5:$C$52,"Sitio web",Menciones!$H$5:$H$52,"Sustantiva") -> 6 | D14: =B14+C14 -> 6 | E14: Sin mención | F14: Sin mención | G14: =IF(OR(C14>0,E14="Sustantiva",F14="Sustantiva"),"Sí","No") -> Sí
A15: Biobío | B15: =COUNTIFS(Menciones!$B$5:$B$52,A15,Menciones!$C$5:$C$52,"Sitio web",Menciones!$H$5:$H$52,"Retórica") -> 2 | C15: =COUNTIFS(Menciones!$B$5:$B$52,A15,Menciones!$C$5:$C$52,"Sitio web",Menciones!$H$5:$H$52,"Sustantiva") -> 0 | D15: =B15+C15 -> 2 | E15: No disponible | F15: Sin mención | G15: =IF(OR(C15>0,E15="Sustantiva",F15="Sustantiva"),"Sí","No") -> No
A16: La Araucanía | B16: =COUNTIFS(Menciones!$B$5:$B$52,A16,Menciones!$C$5:$C$52,"Sitio web",Menciones!$H$5:$H$52,"Retórica") -> 1 | C16: =COUNTIFS(Menciones!$B$5:$B$52,A16,Menciones!$C$5:$C$52,"Sitio web",Menciones!$H$5:$H$52,"Sustantiva") -> 2 | D16: =B16+C16 -> 3 | E16: Sin mención | F16: Sustantiva | G16: =IF(OR(C16>0,E16="Sustantiva",F16="Sustantiva"),"Sí","No") -> Sí
... A20: Magallanes | B20: =COUNTIFS(Menciones!$B$5:$B$52,A20,Menciones!$C$5:$C$52,"Sitio web",Menciones!$H$5:$H$52,"Retórica") -> 1 | C20: =COUNTIFS(Menciones!$B$5:$B$52,A20,Menciones!$C$5:$C$52,"Sitio web",Menciones!$H$5:$H$52,"Sustantiva") -> 0 | D20: =B20+C20 -> 1 | E20: Sin mención | F20: Sustantiva | G20: =IF(OR(C20>0,E20="Sustantiva",F20="Sustantiva"),"Sí","No") -> Sí
A21: Total / n.º GORE | B21: =SUM(B5:B20) -> 24 | C21: =SUM(C5:C20) -> 8 | D21: =SUM(D5:D20) -> 32 | E21: 0 sust. · 1 ret. | F21: 7 sust. · 3 ret. | G21: =COUNTIF(G5:G20,"Sí") -> 8
A23: Indicadores para el texto del paper
A24: GORE con ≥1 mención núcleo en su sitio web | D24: =COUNTIF(D5:D20,">0") -> 13
A25: GORE con mención sustantiva en su sitio web | D25: =COUNTIF(C5:C20,">0") -> 2
A26: % de menciones web que son sustantivas | D26: =IFERROR(C21/D21,0) -> 0.25
A27: Cuentas públicas procesadas (texto legible, total o parcial) | D27: =COUNTIF(E5:E20,"Sin mención*")+COUNTIF(E5:E20,"Retórica")+COUNTIF(E5:E20,"Sustantiva") -> 14
A28: Cuentas públicas con mención núcleo | D28: =COUNTIF(E5:E20,"Retórica")+COUNTIF(E5:E20,"Sustantiva") -> 1
A29: ERD procesadas | D29: =COUNTIF(F5:F20,"Sin mención*")+COUNTIF(F5:F20,"Retórica")+COUNTIF(F5:F20,"Sustantiva") -> 16
A30: ERD con vínculo sustantivo a ODS | D30: =COUNTIF(F5:F20,"Sustantiva") -> 7
A31: Documentos no disponibles o no procesables (de 32) | D31: =COUNTIF(E5:F20,"No disponible")+COUNTIF(E5:F20,"No procesado") -> 2

Sheet Verificacion
A1: Muestra de reproducibilidad (segunda persona)
A2: Anote sus resultados en las columnas amarillas. Parte A: 5 GORE × 4 términos núcleo en el sitio web (semilla aleatoria 2026). Parte B: los 4 términos núcleo en cada documento con mención (cuentas públicas y ERD).
A4: GORE | B4: Fuente | C4: Término / documento | D4: Conteo cod. 1 | E4: Conteo cod. 2 | F4: Coincide | G4: Nombre cod. 2 | H4: Fecha búsqueda 2 | I4: Observaciones
A5: Atacama | B5: Sitio web | C5: ODS | D5: 1 | E5: 1 | F5: =IF(E5="","",IF(ABS(E5-D5)<=1,1,0)) -> 1 | G5: Darling Salazar | H5: 46289
A6: Atacama | B6: Sitio web | C6: Objetivos de Desarrollo Sostenible | D6: 1 | E6: 0 | F6: =IF(E6="","",IF(ABS(E6-D6)<=1,1,0)) -> 1 | G6: Darling Salazar | H6: 46289 | I6: Cod. 2 no halló el término en la noticia del festival 2019; cod. 1 lo contó. Diferencia dentro del margen.
A7: Atacama | B7: Sitio web | C7: Agenda 2030 | D7: 0 | E7: 0 | F7: =IF(E7="","",IF(ABS(E7-D7)<=1,1,0)) -> 1 | G7: Darling Salazar | H7: 46289
A8: Atacama | B8: Sitio web | C8: ODS 16 | D8: 0 | E8: 0 | F8: =IF(E8="","",IF(ABS(E8-D8)<=1,1,0)) -> 1 | G8: Darling Salazar | H8: 46289
A9: Valparaíso | B9: Sitio web | C9: ODS | D9: 2 | E9: 2 | F9: =IF(E9="","",IF(ABS(E9-D9)<=1,1,0)) -> 1 | G9: Darling Salazar | H9: 46289 | I9: Sitio sin buscador; Google site: sin resultados. Se verificaron las 7 noticias del cod. 1 y una muestra aleatoria de 10 noticias (sin menciones).
A10: Valparaíso | B10: Sitio web | C10: Objetivos de Desarrollo Sostenible | D10: 4 | E10: 5 | F10: =IF(E10="","",IF(ABS(E10-D10)<=1,1,0)) -> 1 | G10: Darling Salazar | H10: 46289 | I10: Noticia 2023-03-21 dice «Objetivo de Desarrollo Sostenible» (singular): la regla del cod. 1 no aceptaba singular. Consenso = 5; regla enmendada.
A11: Valparaíso | B11: Sitio web | C11: Agenda 2030 | D11: 2 | E11: 2 | F11: =IF(E11="","",IF(ABS(E11-D11)<=1,1,0)) -> 1 | G11: Darling Salazar | H11: 46289
A12: Valparaíso | B12: Sitio web | C12: ODS 16 | D12: 0 | E12: 0 | F12: =IF(E12="","",IF(ABS(E12-D12)<=1,1,0)) -> 1 | G12: Darling Salazar | H12: 46289
A13: Maule | B13: Sitio web | C13: ODS | D13: 0 | E13: 0 | F13: =IF(E13="","",IF(ABS(E13-D13)<=1,1,0)) -> 1 | G13: Darling Salazar | H13: 46289
A14: Maule | B14: Sitio web | C14: Objetivos de Desarrollo Sostenible | D14: 2 | E14: 2 | F14: =IF(E14="","",IF(ABS(E14-D14)<=1,1,0)) -> 1 | G14: Darling Salazar | H14: 46289 | I14: Página ERD Maule 2042 descartada («objetivos» de la ERD, no ODS). Consenso = 2.
A15: Maule | B15: Sitio web | C15: Agenda 2030 | D15: 0 | E15: 0 | F15: =IF(E15="","",IF(ABS(E15-D15)<=1,1,0)) -> 1 | G15: Darling Salazar | H15: 46289
A16: Maule | B16: Sitio web | C16: ODS 16 | D16: 0 | E16: 0 | F16: =IF(E16="","",IF(ABS(E16-D16)<=1,1,0)) -> 1 | G16: Darling Salazar | H16: 46289
A17: Ñuble | B17: Sitio web | C17: ODS | D17: 3 | E17: 0 | F17: =IF(E17="","",IF(ABS(E17-D17)<=1,1,0)) -> 0 | G17: Darling Salazar | H17: 46289 | I17: Cod. 2 revisó solo los resúmenes de la lista de resultados; al abrir las 3 noticias, todas contienen «ODS». Consenso = 3.
A18: Ñuble | B18: Sitio web | C18: Objetivos de Desarrollo Sostenible | D18: 3 | E18: 0 | F18: =IF(E18="","",IF(ABS(E18-D18)<=1,1,0)) -> 0 | G18: Darling Salazar | H18: 46289 | I18: Ídem: revisión solo de resúmenes. Al abrir las 3 noticias, todas contienen el término. Consenso = 3.
A19: Ñuble | B19: Sitio web | C19: Agenda 2030 | D19: 0 | E19: 0 | F19: =IF(E19="","",IF(ABS(E19-D19)<=1,1,0)) -> 1 | G19: Darling Salazar | H19: 46289 | I19: Cod. 2 corrigió un error de digitación (1 → 0).
A20: Ñuble | B20: Sitio web | C20: ODS 16 | D20: 0 | E20: 0 | F20: =IF(E20="","",IF(ABS(E20-D20)<=1,1,0)) -> 1 | G20: Darling Salazar | H20: 46289
A21: Biobío | B21: Sitio web | C21: ODS | D21: 1 | E21: 1 | F21: =IF(E21="","",IF(ABS(E21-D21)<=1,1,0)) -> 1 | G21: Darling Salazar | H21: 46289
A22: Biobío | B22: Sitio web | C22: Objetivos de Desarrollo Sostenible | D22: 1 | E22: 2 | F22: =IF(E22="","",IF(ABS(E22-D22)<=1,1,0)) -> 1 | G22: Darling Salazar | H22: 46289 | I22: La regla inicial del cod. 1 no aceptaba «del» («objetivos del desarrollo sostenible», 2021). Consenso = 2.
A23: Biobío | B23: Sitio web | C23: Agenda 2030 | D23: 1 | E23: 1 | F23: =IF(E23="","",IF(ABS(E23-D23)<=1,1,0)) -> 1 | G23: Darling Salazar | H23: 46289
A24: Biobío | B24: Sitio web | C24: ODS 16 | D24: 0 | E24: 0 | F24: =IF(E24="","",IF(ABS(E24-D24)<=1,1,0)) -> 1 | G24: Darling Salazar | H24: 46289
A26: Parte B · Documentos (cuentas públicas y ERD con mención)
A27: Cómo contar: abra el PDF (enlace en la hoja «Documentos»), use Ctrl+F / Cmd+F con cada término y anote cuántos resultados da el visor. Para «Objetivos de Desarrollo Sostenible» busque «desarrollo sostenible» y cuente solo los precedidos por «Objetivo(s) de/del». «ODS» también encuentra «ODS 16»: está bien, se cuenta igual que el cod. 1. No cuente encabezados de columna ni direcciones web (en la ERD de Magallanes, Ctrl+F encuentra además el encabezado «ods» de las 58 tablas de indicadores: réstelo). Coincide si la diferencia es ≤ 1 o ≤ 10 % del conteo del cod. 1 (el texto de un PDF puede cortar palabras entre líneas). Se cuenta solo texto: un ODS 16 que aparece como ícono o número en una tabla no suma aquí (eso se registra en el mapa de 17 ODS).
A28: Antofagasta | B28: Cuenta pública | C28: ODS — Cuenta Pública Gobierno Regional 2024 (publicada 04-02-2026) | D28: 0 | F28: =IF(E28="","",IF(ABS(E28-D28)<=MAX(1,0.1*D28),1,0))
A29: Antofagasta | B29: Cuenta pública | C29: Objetivos de Desarrollo Sostenible — Cuenta Pública Gobierno Regional 2024 (publicada 04-02-2026) | D29: 1 | F29: =IF(E29="","",IF(ABS(E29-D29)<=MAX(1,0.1*D29),1,0))
A30: Antofagasta | B30: Cuenta pública | C30: Agenda 2030 — Cuenta Pública Gobierno Regional 2024 (publicada 04-02-2026) | D30: 0 | F30: =IF(E30="","",IF(ABS(E30-D30)<=MAX(1,0.1*D30),1,0))
